{"uuid": "c797120d-c77f-4ddd-bed3-40229bb58b4d", "children": ["0ecc4a01-fd4c-43c6-94f5-5cd741f5832b", "b539c42a-feb2-4a41-a6c3-6d4a83f1aeee", "336c46b4-464b-4b11-b051-ab355c3f173b", "691ba1f8-906a-438b-8062-99178507e57f"], "befores": [{"name": "InitDesktopDriver", "status": "broken", "statusDetails": {"message": "urllib3.exceptions.MaxRetryError: HTTPConnectionPool(host='127.0.0.1', port=4723): Max retries exceeded with url: /session (Caused by NewConnectionError('<urllib3.connection.HTTPConnection object at 0x0000027A0AA04FA0>: Failed to establish a new connection: [WinError 10061] No connection could be made because the target machine actively refused it'))\n", "trace": "  File \"C:\\Users\\serge\\AppData\\Local\\Programs\\Python\\Python310\\lib\\site-packages\\pluggy\\_callers.py\", line 39, in _multicall\n    res = hook_impl.function(*args)\n  File \"C:\\Users\\serge\\AppData\\Local\\Programs\\Python\\Python310\\lib\\site-packages\\_pytest\\fixtures.py\", line 1121, in pytest_fixture_setup\n    result = call_fixture_func(fixturefunc, request, kwargs)\n  File \"C:\\Users\\serge\\AppData\\Local\\Programs\\Python\\Python310\\lib\\site-packages\\_pytest\\fixtures.py\", line 893, in call_fixture_func\n    fixture_result = next(generator)\n  File \"D:\\AtidAutomation\\FullStackFinalProject\\TestCases\\conftest.py\", line 212, in InitDesktopDriver\n    edriver = GetDesktopDriver()\n  File \"D:\\AtidAutomation\\FullStackFinalProject\\TestCases\\conftest.py\", line 228, in GetDesktopDriver\n    driver = appium.webdriver.Remote(GetData(\"WinAppDriverService\"), dc)\n  File \"C:\\Users\\serge\\AppData\\Local\\Programs\\Python\\Python310\\lib\\site-packages\\appium\\webdriver\\webdriver.py\", line 267, in __init__\n    super().__init__(\n  File \"C:\\Users\\serge\\AppData\\Local\\Programs\\Python\\Python310\\lib\\site-packages\\selenium\\webdriver\\remote\\webdriver.py\", line 272, in __init__\n    self.start_session(capabilities, browser_profile)\n  File \"C:\\Users\\serge\\AppData\\Local\\Programs\\Python\\Python310\\lib\\site-packages\\appium\\webdriver\\webdriver.py\", line 357, in start_session\n    response = self.execute(RemoteCommand.NEW_SESSION, parameters)\n  File \"C:\\Users\\serge\\AppData\\Local\\Programs\\Python\\Python310\\lib\\site-packages\\selenium\\webdriver\\remote\\webdriver.py\", line 427, in execute\n    response = self.command_executor.execute(driver_command, params)\n  File \"C:\\Users\\serge\\AppData\\Local\\Programs\\Python\\Python310\\lib\\site-packages\\selenium\\webdriver\\remote\\remote_connection.py\", line 344, in execute\n    return self._request(command_info[0], url, body=data)\n  File \"C:\\Users\\serge\\AppData\\Local\\Programs\\Python\\Python310\\lib\\site-packages\\selenium\\webdriver\\remote\\remote_connection.py\", line 366, in _request\n    response = self._conn.request(method, url, body=body, headers=headers)\n  File \"C:\\Users\\serge\\AppData\\Local\\Programs\\Python\\Python310\\lib\\site-packages\\urllib3\\request.py\", line 78, in request\n    return self.request_encode_body(\n  File \"C:\\Users\\serge\\AppData\\Local\\Programs\\Python\\Python310\\lib\\site-packages\\urllib3\\request.py\", line 170, in request_encode_body\n    return self.urlopen(method, url, **extra_kw)\n  File \"C:\\Users\\serge\\AppData\\Local\\Programs\\Python\\Python310\\lib\\site-packages\\urllib3\\poolmanager.py\", line 376, in urlopen\n    response = conn.urlopen(method, u.request_uri, **kw)\n  File \"C:\\Users\\serge\\AppData\\Local\\Programs\\Python\\Python310\\lib\\site-packages\\urllib3\\connectionpool.py\", line 815, in urlopen\n    return self.urlopen(\n  File \"C:\\Users\\serge\\AppData\\Local\\Programs\\Python\\Python310\\lib\\site-packages\\urllib3\\connectionpool.py\", line 815, in urlopen\n    return self.urlopen(\n  File \"C:\\Users\\serge\\AppData\\Local\\Programs\\Python\\Python310\\lib\\site-packages\\urllib3\\connectionpool.py\", line 815, in urlopen\n    return self.urlopen(\n  File \"C:\\Users\\serge\\AppData\\Local\\Programs\\Python\\Python310\\lib\\site-packages\\urllib3\\connectionpool.py\", line 787, in urlopen\n    retries = retries.increment(\n  File \"C:\\Users\\serge\\AppData\\Local\\Programs\\Python\\Python310\\lib\\site-packages\\urllib3\\util\\retry.py\", line 592, in increment\n    raise MaxRetryError(_pool, url, error or ResponseError(cause))\n"}, "start": 1666689596197, "stop": 1666689604365}], "start": 1666689596197, "stop": 1666689605541}